Workbook
Name Slicer_Months__Week_Start_Date: #N/A
Name Slicer_Months__Week_Start_Date1: #N/A

Sheet Task 1 & 2 
A1: Content Type | B1: (All) | G1: Top 10 posts with highest engagement.
A2: Average engagement rate per platform | G2: Post ID | H2: Platform | I2: Date | J2: Content Type | K2: Post Text | L2: Likes | M2: Shares | N2: Comments | O2: Engagement Rate | P2: Engagement
A3: Row Labels | B3: Average of Engagement Rate | G3: P061 | H3: Twitter | I3: 45540 | J3: Video | K3: Check out our latest video on twitter! | L3: 4886 | M3: 983 | N3: 409 | O3: 0.14 | P3: 6278
A4: Facebook | B4: 0.1219729 | G4: P144 | H4: YouTube | I4: 45593 | J4: Story | K4: Check out our latest story on youtube! | L4: 4929 | M4: 749 | N4: 452 | O4: 0.07 | P4: 6130
A5: Instagram | B5: 0.19329258 | G5: P164 | H5: YouTube | I5: 45715 | J5: Text | K5: Check out our latest text on youtube! | L5: 4934 | M5: 971 | N5: 156 | O5: 0.15 | P5: 6061
A6: Twitter | B6: 0.14432836 | G6: P261 | H6: Instagram | I6: 45592 | J6: Image | K6: Check out our latest image on instagram! | L6: 4853 | M6: 837 | N6: 340 | O6: 0.08 | P6: 6030
A7: YouTube | B7: 0.13118494 | G7: P244 | H7: YouTube | I7: 45590 | J7: Video | K7: Check out our latest video on youtube! | L7: 4661 | M7: 935 | N7: 433 | O7: 0.26 | P7: 6029
G8: P215 | H8: Facebook | I8: 45783 | J8: Image | K8: Check out our latest image on facebook! | L8: 4872 | M8: 925 | N8: 176 | O8: 0.07 | P8: 5973
A9: Total Likes, Shares, and Comments by Content Type and Platform | G9: P106 | H9: Instagram | I9: 45692 | J9: Image | K9: Check out our latest image on instagram! | L9: 4619 | M9: 821 | N9: 499 | O9: 0.09 | P9: 5939
A10: Row Labels | B10: Likes count | C10: Shares count | D10: Comments count
A11: Facebook | B11: 242761 | C11: 39181 | D11: 23300
A12: Carousel | B12: 44476 | C12: 7400 | D12: 4589 | F12: Average Clicks per post by Hashtag.
A13: Image | B13: 71602 | C13: 12904 | D13: 6495 | F13: Row Labels | G13: Total clicks for hashtag
A14: Reel | B14: 36368 | C14: 5964 | D14: 3353 | F14: #AnytimeIsPepsiTime | G14: 2418
A15: Story | B15: 29405 | C15: 4950 | D15: 3223 | F15: #BetterWithPepsi | G15: 804
A16: Text | B16: 31963 | C16: 4792 | D16: 3377 | F16: #LiveForNow | G16: 14717
A17: Video | B17: 28947 | C17: 3171 | D17: 2263 | F17: #PepsiCoRefresh | G17: 16976
A18: Instagram | B18: 204284 | C18: 41444 | D18: 17851 | F18: #SmoothLikeNitroPepsi | G18: 559
A19: Carousel | B19: 43948 | C19: 6975 | D19: 3890 | F19: #ThirstyForMore | G19: 15456
A20: Image | B20: 34202 | C20: 5286 | D20: 2655
A21: Reel | B21: 32148 | C21: 8110 | D21: 3386
A22: Story | B22: 42649 | C22: 10049 | D22: 3846
A23: Text | B23: 25567 | C23: 5112 | D23: 1946
A24: Video | B24: 25770 | C24: 5912 | D24: 2128
A25: Twitter | B25: 196730 | C25: 32851 | D25: 20103
A26: Carousel | B26: 48649 | C26: 5791 | D26: 3607
A27: Image | B27: 40669 | C27: 7004 | D27: 4834
A28: Reel | B28: 27029 | C28: 4550 | D28: 1913
A29: Story | B29: 18891 | C29: 4319 | D29: 2540
A30: Text | B30: 31899 | C30: 4861 | D30: 3910
A31: Video | B31: 29593 | C31: 6326 | D31: 3299
... A39: Grand Total | B39: 815324 | C39: 142048 | D39: 74074
A42: For highlight top-performing hashtags using a formula-based ranking
A43: I have created another table just beside post table in Posts worksheet.
A44: Please check Posts worksheet

Sheet Task 3
A1: 1 - Identify which Platform generates the highest engagement
A2: Row Labels | B2: Average of Engagement_Rate | M2: Row Labels | N2: Sum of Likes | O2: Sum of Shares | P2: Sum of Comments | Q2: Engagement(likes+shares+comments)
A3: Facebook | B3: 5.6486 | M3: Facebook | N3: 242761 | O3: 39181 | P3: 23300 | Q3: 305242
A4: Instagram | B4: 5.7156 | M4: Instagram | N4: 204284 | O4: 41444 | P4: 17851 | Q4: 263579
A5: Twitter | B5: 5.6558 | M5: Twitter | N5: 196730 | O5: 32851 | P5: 20103 | Q5: 249684
A6: YouTube | B6: 5.5588 | M6: YouTube | N6: 171549 | O6: 28572 | P6: 12820 | Q6: 212941
A8: Instagram generates the highest overall engagement rate | M8: Facebook has minute less overall engagement than Instagram but few fields such as likes, shares and comments are little more on it
A11: 2 - Compare Growth rates of followers across different platforms.
A12: Row Labels | B12: Sum of New_Followers
A13: Facebook | B13: 50862
A14: Instagram | B14: 58311
A15: Twitter | B15: 53484
A16: YouTube | B16: 47471
A28: 3 - Visualize the engagement by ad spend across Platform
A29: Row Labels | B29: Sum of Ad_Spend | C29: Average of Engagement_Rate
A30: Facebook | B30: 1379539 | C30: 5.6486
A31: Instagram | B31: 1164373 | C31: 5.7156
A32: Twitter | B32: 1060357 | C32: 5.6558
A33: YouTube | B33: 1228647 | C33: 5.5588
A36: Amount spend on Instagram Ads are less and engagement rate is high.
A45: 4 - Advise whether to focus on 1–2 core platforms or continue multi-platform strategy. Justify the opinion by the analysis
A46: Based on a comprehensive analysis of this data, the best strategy is to continue with a multi-platform approach but adopt a tiered focus strategy.
A47: Insights from this data shows that over all engagement considering all fields is little more on Instagram which is engaging more audience but at the same time few elements such as likes, comments and shares are litlle more on facebook which also helps in marketing of products.
A48: By visualization on expenditure of ads and it effects on engagement we come to know that company has spend less on instagram ads but has still increased little more engagement rate as compared to other platforms where company has invested more on ads.
A49: If we see a big picture of this analysis we come to know that all platforms are contributing for company's marketing and helping to reach large numbers of audience, it is just that few are contributing more as compared to others like intagram and facebook.
A50: Instead of treating all platforms equally or dropping some entirely, company should categorize them and focus little more on top tier platform like Instagram and facebook where audience engagement is more.
A51: At the same time company can do another analysis to find root causes of why other platforms are not getting good engagement rates and improve them simultaneously to get improvements and better results as compared to the present.
A52: By adopting this approach, company can invest wisely, play to the strengths of each platform, and continue to grow effectively without abandoning the unique advantages that each one provides.

Sheet Task 4
A1: 1]A - Most frequently used hashtags
A3: Row Labels | B3: Count of ALL Hashtags
A4: #PepsiCoRefresh | B4: 107
A5: #ThirstyForMore | B5: 102
A6: #LiveForNow | B6: 101
A7: #AnytimeIsPepsiTime | B7: 15
A8: #BetterWithPepsi | B8: 7
A9: #SmoothLikeNitroPepsi | B9: 5
A11: Most frequently used hashtags are #PepsiCoRefresh and #ThirstyForMore
A13: 1]B - Average performance (likes, comments) of posts containing each hashtag.
A15: Row Labels | B15: Average Likes | C15: Average Comments | D15: Average Performance of Posts for each Hashtag
A16: #AnytimeIsPepsiTime | B16: 2219.6 | C16: 257.4 | D16: 2477
A17: #BetterWithPepsi | B17: 3451.7143 | C17: 151 | D17: 3602.7143
A18: #LiveForNow | B18: 2640.6832 | C18: 260.0099 | D18: 2900.6931
A19: #PepsiCoRefresh | B19: 2705.1028 | C19: 254.18692 | D19: 2959.2897
A20: #SmoothLikeNitroPepsi | B20: 3127.8 | C20: 283.4 | D20: 3411.2
A21: #ThirstyForMore | B21: 2838.8039 | C21: 230.95098 | D21: 3069.7549
A24: 2 - Compare performance of videos vs. images vs. carousels across platforms.
A26: Row Labels | B26: Avg. Performance
A27: Carousel | B27: 202978
A28: Facebook | B28: 56465
A29: Instagram | B29: 54813
A30: Twitter | B30: 58047
A31: YouTube | B31: 33653
A32: Image | B32: 215941
A33: Facebook | B33: 91001
A34: Instagram | B34: 42143
A35: Twitter | B35: 52507
A36: YouTube | B36: 30290
A37: Video | B37: 146869
A38: Facebook | B38: 34381
... A41: YouTube | B41: 39460
A44: 3 - Recommend which content types should be prioritized on which platform
A46: Row Labels | B46: Avg. Engagement(Likes, shares, comments)
A47: Facebook | B47: 305242
A48: Carousel | B48: 56465
A49: Image | B49: 91001
A50: Reel | B50: 45685
A51: Story | B51: 37578
A52: Text | B52: 40132
...

Sheet Task 5
A1: 1 - Total and average impressions, likes, and clicks per campaign
A3: Row Labels | B3: Total Impressions | C3: Total Likes | D3: Total Clicks | E3: Average Impressions | F3: Average Likes | G3: Average Clicks
A4: DailyWellness | B4: 2439664 | C4: 186334 | D4: 10672 | E4: 34852.343 | F4: 2661.9143 | G4: 152.45714
A5: FestiveRadiance | B5: 1986356 | C5: 159783 | D5: 9872 | E5: 34247.517 | F5: 2754.8793 | G5: 170.2069
A6: NewYearRefresh | B6: 2266053 | C6: 183346 | D6: 10032 | E6: 33821.687 | F6: 2736.5075 | G6: 149.73134
A7: SummerSplash | B7: 1846272 | C7: 138793 | D7: 6434 | E7: 38464 | F7: 2891.5208 | G7: 134.04167
A10: 2- Engagement uplift during vs. before the campaign period.
A12: Campaign_Name | B12: Campaign Period | C12: Average Engagement
A13: SummerSplash | B13: During | C13: 3765.4
A14: SummerSplash | B14: Before | C14: 2865
A15: NewYearRefresh | B15: Before | C15: 3480.6667
A16: NewYearRefresh | B16: During | C16: 3140.6667
A17: FestiveRadiance | B17: During | C17: 3841.8571
A18: FestiveRadiance | B18: Before | C18: 3512.25
A19: DailyWellness | B19: Before | C19: 3931.1111
A20: DailyWellness | B20: During | C20: 3009.5
A23: 3 - Which campaign had the highest ROI in terms of engagement vs. budget.
A25: Row Labels | B25: Total Engagement | C25: Total Budget | D25: (ROI)Engagements per $1000
A26: DailyWellness | B26: 237651 | C26: =VLOOKUP(A26, 'Campaign Metadata'!A:E, 5, FALSE) -> 180000 | D26: =(B26/C26)*1000 -> 1320.2833
A27: FestiveRadiance | B27: 201739 | C27: =VLOOKUP(A27, 'Campaign Metadata'!A:E, 5, FALSE) -> 200000 | D27: =(B27/C27)*1000 -> 1008.695
A28: NewYearRefresh | B28: 232821 | C28: =VLOOKUP(A28, 'Campaign Metadata'!A:E, 5, FALSE) -> 250000 | D28: =(B28/C28)*1000 -> 931.284
A29: SummerSplash | B29: 173901 | C29: =VLOOKUP(A29, 'Campaign Metadata'!A:E, 5, FALSE) -> 150000 | D29: =(B29/C29)*1000 -> 1159.34
A32: 4 - Which campaign had the strongest follower growth impact.
A35: Campaign_Name | B35: Start_Date | C35: End_Date | D35: Total New Followers
A36: SummerSplash | B36: 2024-06-15 | C36: 2024-07-15 | D36: =SUMIFS('Engagement Summary'!C:C, 'Engagement Summary'!A:A, ">="&B36, 'Engagement Summary'!A:A, "<="&C36) -> 18105
A37: FestiveRadiance | B37: 2024-10-01 | C37: 2024-10-31 | D37: =SUMIFS('Engagement Summary'!C:C, 'Engagement Summary'!A:A, ">="&B37, 'Engagement Summary'!A:A, "<="&C37) -> 14518
A38: NewYearRefresh | B38: 2024-12-25 | C38: 2025-01-10 | D38: =SUMIFS('Engagement Summary'!C:C, 'Engagement Summary'!A:A, ">="&B38, 'Engagement Summary'!A:A, "<="&C38) -> 11428
A39: DailyWellness | B39: 2025-03-01 | C39: 2025-03-31 | D39: =SUMIFS('Engagement Summary'!C:C, 'Engagement Summary'!A:A, ">="&B39, 'Engagement Summary'!A:A, "<="&C39) -> 20682
A41: DailyWellness campaign had the strongest follower growth impact.

Sheet Task 6
A1: 1 - Visualize weekly follower growth trends by platform using line charts.
A3: Sum of New_Followers | B3: Column Labels
A4: Row Labels | B4: Facebook | C4: Instagram | D4: Twitter | E4: YouTube
A5: 45474 | B5: 505 | C5: 226 | D5: 1420 | E5: 144
A6: 45481 | B6: 350 | C6: 1757 | D6: 987 | E6: 883
A7: 45488 | B7: 170 | C7: 1960 | D7: 704 | E7: 224
A8: 45495 | B8: 1391 | C8: 508 | D8: 1701 | E8: 804
A9: 45502 | B9: 160 | C9: 653 | D9: 1756 | E9: 576
A11: Visualizing weekly follower growth by platform for all the data in weeks column was not a good idea.
A12: Therefore I have created a month slicer to make visualization of trends more understandable and clean.
A13: Monthly slicer visuaizes weekly follower growth trend by platform for particular month.
A18: 2 - Identify the week with the highest net follower gain.
A21: Row Labels | B21: Net Follower Gain
A22: 45656 | B22: 6530 | D22: The week with the highest net follower gain is the week that starts on 30-12-2024
A23: 45698 | B23: 5281
A24: 45642 | B24: 5044
A25: 45712 | B25: 4806
A26: 45628 | B26: 4795
A27: 45635 | B27: 4792
A28: 45782 | B28: 4594
A29: 45600 | B29: 4584
A30: 45544 | B30: 4360
A31: 45747 | B31: 4298
A32: 45733 | B32: 4042
A33: 45768 | B33: 4040
A34: 45621 | B34: 4008
... A71: 45761 | B71: -137
A74: 3 - Create a moving average chart to smooth out follower growth trends.
A77: Sum of Total_Followers | B77: Column Labels
A78: Row Labels | B78: Facebook | C78: Instagram | D78: Twitter | E78: YouTube
A79: 45663 | B79: 95728 | C79: 466382 | D79: 371156 | E79: 95410
A80: 45670 | B80: 224699 | C80: 349413 | D80: 487896 | E80: 14437
A81: 45677 | B81: 479490 | C81: 383681 | D81: 124404 | E81: 336949
A82: 45684 | B82: 321307 | C82: 357265 | D82: 262569 | E82: 461669
A98: 6 - Determine the correlation between ad spend and follower growth using scatter plots and basic correlation calculation
A100: Correlation (Ad Spend vs. New Followers):
A101: =CORREL('Engagement Summary'!C:C, 'Engagement Summary'!G:G) -> 0.080963093

Sheet ExplainationLink
B1: Link to video explanation of the project
B2: https://drive.google.com/file/d/1e-KwhWrpeNGaI4--_YquDjqIlHGraPyg/view?usp=sharing

Sheet Posts
A1: Post ID | B1: Platform | C1: Date | D1: Content Type | E1: Post Text | F1: Likes | G1: Shares | H1: Comments | I1: Impressions | J1: Reach | K1: Clicks | L1: Hashtags Used | M1: Campaign_Name | N1: Hashtags 1 | O1: Hashtag 2 | P1: Hashtag 3 | Q1: Engagement Rate | R1: Engagement | T1: Clicks for all hashtags | U1: ALL Hashtags | V1: Rank of Clicks
A2: P001 | B2: Twitter | C2: 2024-12-23 | D2: Reel | E2: Check out our latest reel on twitter! | F2: 1461 | G2: 184 | H2: 344 | I2: 21915 | J2: 21675 | K2: 15 | L2: #LiveForNow,#AnytimeIsPepsiTime | M2: SummerSplash | N2: #LiveForNow | O2: #AnytimeIsPepsiTime | Q2: =(F2+G2+H2)/I2 -> 0.090759754 | R2: =F2+G2+H2 -> 1989 | T2: 15 | U2: #LiveForNow | V2: =RANK(T2, T:T) -> 323 | X2: Likes | Y2: Comments | Z2: All hashtags | AA2: Performance
A3: P002 | B3: Twitter | C3: 2025-04-03 | D3: Text | E3: Check out our latest text on twitter! | F3: 4054 | G3: 389 | H3: 493 | I3: 64864 | J3: 64383 | K3: 117 | L3: #PepsiCoRefresh,#BetterWithPepsi | M3: FestiveRadiance | N3: #PepsiCoRefresh | O3: #BetterWithPepsi | Q3: =(F3+G3+H3)/I3 -> 0.076097681 | R3: =F3+G3+H3 -> 4936 | T3: 15 | U3: #AnytimeIsPepsiTime | V3: =RANK(T3, T:T) -> 323 | X3: 1461 | Y3: 344 | Z3: #LiveForNow | AA3: =X3+Y3 -> 1805
A4: P003 | B4: YouTube | C4: 2025-05-12 | D4: Reel | E4: Check out our latest reel on youtube! | F4: 2795 | G4: 105 | H4: 49 | I4: 53105 | J4: 52307 | K4: 204 | L4: #PepsiCoRefresh | M4: NewYearRefresh | N4: #PepsiCoRefresh | Q4: =(F4+G4+H4)/I4 -> 0.055531494 | R4: =F4+G4+H4 -> 2949 | T4: 117 | U4: #PepsiCoRefresh | V4: =RANK(T4, T:T) -> 213 | X4: 1461 | Y4: 344 | Z4: #AnytimeIsPepsiTime | AA4: =X4+Y4 -> 1805
A5: P004 | B5: Instagram | C5: 2024-08-12 | D5: Story | E5: Check out our latest story on instagram! | F5: 2404 | G5: 363 | H5: 138 | I5: 19232 | J5: 18636 | K5: 128 | L5: #ThirstyForMore | M5: DailyWellness | N5: #ThirstyForMore | Q5: =(F5+G5+H5)/I5 -> 0.15105033 | R5: =F5+G5+H5 -> 2905 | T5: 117 | U5: #BetterWithPepsi | V5: =RANK(T5, T:T) -> 213 | X5: 4054 | Y5: 493 | Z5: #PepsiCoRefresh | AA5: =X5+Y5 -> 4547
A6: P005 | B6: YouTube | C6: 2024-06-26 | D6: Reel | E6: Check out our latest reel on youtube! | F6: 3557 | G6: 687 | H6: 424 | I6: 71140 | J6: 70701 | K6: 224 | L6: #ThirstyForMore,#PepsiCoRefresh | M6: SummerSplash | N6: #ThirstyForMore | O6: #PepsiCoRefresh | Q6: =(F6+G6+H6)/I6 -> 0.065617093 | R6: =F6+G6+H6 -> 4668 | T6: 204 | U6: #PepsiCoRefresh | V6: =RANK(T6, T:T) -> 115 | X6: 4054 | Y6: 493 | Z6: #BetterWithPepsi | AA6: =X6+Y6 -> 4547
A7: P006 | B7: Facebook | C7: 2024-10-31 | D7: Carousel | E7: Check out our latest carousel on facebook! | F7: 2945 | G7: 930 | H7: 355 | I7: 23560 | J7: 23275 | K7: 256 | L7: #PepsiCoRefresh | M7: FestiveRadiance | N7: #PepsiCoRefresh | Q7: =(F7+G7+H7)/I7 -> 0.1795416 | R7: =F7+G7+H7 -> 4230 | T7: 128 | U7: #ThirstyForMore | V7: =RANK(T7, T:T) -> 199 | X7: 2795 | Y7: 49 | Z7: #PepsiCoRefresh | AA7: =X7+Y7 -> 2844
A8: P007 | B8: Twitter | C8: 2024-06-24 | D8: Carousel | E8: Check out our latest carousel on twitter! | F8: 3860 | G8: 201 | H8: 279 | I8: 61760 | J8: 61660 | K8: 235 | L8: #PepsiCoRefresh | M8: FestiveRadiance | N8: #PepsiCoRefresh | Q8: =(F8+G8+H8)/I8 -> 0.070272021 | R8: =F8+G8+H8 -> 4340 | T8: 224 | U8: #ThirstyForMore | V8: =RANK(T8, T:T) -> 88 | X8: 2404 | Y8: 138 | Z8: #ThirstyForMore | AA8: =X8+Y8 -> 2542
A9: P008 | B9: YouTube | C9: 2024-07-13 | D9: Image | E9: Check out our latest image on youtube! | F9: 3929 | G9: 262 | H9: 278 | I9: 43219 | J9: 42841 | K9: 39 | L9: #ThirstyForMore | M9: DailyWellness | N9: #ThirstyForMore | Q9: =(F9+G9+H9)/I9 -> 0.1034036 | R9: =F9+G9+H9 -> 4469 | T9: 224 | U9: #PepsiCoRefresh | V9: =RANK(T9, T:T) -> 88 | X9: 3557 | Y9: 424 | Z9: #ThirstyForMore | AA9: =X9+Y9 -> 3981
A10: P009 | B10: Facebook | C10: 2024-08-30 | D10: Text | E10: Check out our latest text on facebook! | F10: 3784 | G10: 808 | H10: 404 | I10: 56760 | J10: 56343 | K10: 131 | L10: #PepsiCoRefresh | M10: FestiveRadiance | N10: #PepsiCoRefresh | Q10: =(F10+G10+H10)/I10 -> 0.088019732 | R10: =F10+G10+H10 -> 4996 | T10: 256 | U10: #PepsiCoRefresh | V10: =RANK(T10, T:T) -> 40 | X10: 3557 | Y10: 424 | Z10: #PepsiCoRefresh | AA10: =X10+Y10 -> 3981
A11: P010 | B11: Facebook | C11: 2025-03-11 | D11: Image | E11: Check out our latest image on facebook! | F11: 4241 | G11: 902 | H11: 47 | I11: 72097 | J11: 71598 | K11: 167 | L11: #PepsiCoRefresh | M11: FestiveRadiance | N11: #PepsiCoRefresh | Q11: =(F11+G11+H11)/I11 -> 0.071986352 | R11: =F11+G11+H11 -> 5190 | T11: 235 | U11: #PepsiCoRefresh | V11: =RANK(T11, T:T) -> 70 | X11: 2945 | Y11: 355 | Z11: #PepsiCoRefresh | AA11: =X11+Y11 -> 3300
A12: P011 | B12: Instagram | C12: 2025-02-02 | D12: Story | E12: Check out our latest story on instagram! | F12: 1792 | G12: 614 | H12: 497 | I12: 25088 | J12: 24675 | K12: 65 | L12: #LiveForNow | M12: DailyWellness | N12: #LiveForNow | Q12: =(F12+G12+H12)/I12 -> 0.11571269 | R12: =F12+G12+H12 -> 2903 | T12: 39 | U12: #ThirstyForMore | V12: =RANK(T12, T:T) -> 290 | X12: 3860 | Y12: 279 | Z12: #PepsiCoRefresh | AA12: =X12+Y12 -> 4139
A13: P012 | B13: Facebook | C13: 2024-07-21 | D13: Reel | E13: Check out our latest reel on facebook! | F13: 1946 | G13: 686 | H13: 377 | I13: 23352 | J13: 22982 | K13: 213 | L13: #LiveForNow | M13: NewYearRefresh | N13: #LiveForNow | Q13: =(F13+G13+H13)/I13 -> 0.12885406 | R13: =F13+G13+H13 -> 3009 | T13: 131 | U13: #PepsiCoRefresh | V13: =RANK(T13, T:T) -> 193 | X13: 3929 | Y13: 278 | Z13: #ThirstyForMore | AA13: =X13+Y13 -> 4207
A14: P013 | B14: YouTube | C14: 2024-11-18 | D14: Carousel | E14: Check out our latest carousel on youtube! | F14: 1171 | G14: 286 | H14: 231 | I14: 22249 | J14: 21282 | K14: 114 | L14: #ThirstyForMore | M14: SummerSplash | N14: #ThirstyForMore | Q14: =(F14+G14+H14)/I14 -> 0.075868578 | R14: =F14+G14+H14 -> 1688 | T14: 167 | U14: #PepsiCoRefresh | V14: =RANK(T14, T:T) -> 160 | X14: 3784 | Y14: 404 | Z14: #PepsiCoRefresh | AA14: =X14+Y14 -> 4188
A15: P014 | B15: Facebook | C15: 2025-02-16 | D15: Story | E15: Check out our latest story on facebook! | F15: 4242 | G15: 555 | H15: 131 | I15: 33936 | J15: 33802 | K15: 265 | L15: #LiveForNow | N15: #LiveForNow | Q15: =(F15+G15+H15)/I15 -> 0.14521452 | R15: =F15+G15+H15 -> 4928 | T15: 65 | U15: #LiveForNow | V15: =RANK(T15, T:T) -> 259 | X15: 4241 | Y15: 47 | Z15: #PepsiCoRefresh | AA15: =X15+Y15 -> 4288
A16: P015 | B16: Facebook | C16: 2024-10-24 | D16: Video | E16: Check out our latest video on facebook! | F16: 3888 | G16: 604 | H16: 128 | I16: 77760 | J16: 77167 | K16: 20 | L16: #LiveForNow | M16: SummerSplash | N16: #LiveForNow | Q16: =(F16+G16+H16)/I16 -> 0.05941358 | R16: =F16+G16+H16 -> 4620 | T16: 213 | U16: #LiveForNow | V16: =RANK(T16, T:T) -> 100 | X16: 1792 | Y16: 497 | Z16: #LiveForNow | AA16: =X16+Y16 -> 2289
A17: P016 | B17: Facebook | C17: 2024-08-26 | D17: Text | E17: Check out our latest text on facebook! | F17: 3452 | G17: 377 | H17: 360 | I17: 55232 | J17: 55075 | K17: 87 | L17: #LiveForNow | M17: NewYearRefresh | N17: #LiveForNow | Q17: =(F17+G17+H17)/I17 -> 0.075843714 | R17: =F17+G17+H17 -> 4189 | T17: 114 | U17: #ThirstyForMore | V17: =RANK(T17, T:T) -> 217 | X17: 1946 | Y17: 377 | Z17: #LiveForNow | AA17: =X17+Y17 -> 2323
A18: P017 | B18: Facebook | C18: 2025-05-05 | D18: Text | E18: Check out our latest text on facebook! | F18: 4441 | G18: 511 | H18: 70 | I18: 53292 | J18: 53082 | K18: 159 | L18: #ThirstyForMore | M18: DailyWellness | N18: #ThirstyForMore | Q18: =(F18+G18+H18)/I18 -> 0.094235533 | R18: =F18+G18+H18 -> 5022 | T18: 265 | U18: #LiveForNow | V18: =RANK(T18, T:T) -> 35 | X18: 1171 | Y18: 231 | Z18: #ThirstyForMore | AA18: =X18+Y18 -> 1402
A19: P018 | B19: Instagram | C19: 2024-08-19 | D19: Reel | E19: Check out our latest reel on instagram! | F19: 3000 | G19: 382 | H19: 325 | I19: 36000 | J19: 35819 | K19: 19 | L19: #LiveForNow | M19: SummerSplash | N19: #LiveForNow | Q19: =(F19+G19+H19)/I19 -> 0.10297222 | R19: =F19+G19+H19 -> 3707 | T19: 20 | U19: #LiveForNow | V19: =RANK(T19, T:T) -> 316 | X19: 4242 | Y19: 131 | Z19: #LiveForNow | AA19: =X19+Y19 -> 4373
A20: P019 | B20: Instagram | C20: 2024-06-23 | D20: Video | E20: Check out our latest video on instagram! | F20: 1071 | G20: 519 | H20: 22 | I20: 16065 | J20: 15865 | K20: 103 | L20: #PepsiCoRefresh | M20: DailyWellness | N20: #PepsiCoRefresh | Q20: =(F20+G20+H20)/I20 -> 0.10034236 | R20: =F20+G20+H20 -> 1612 | T20: 87 | U20: #LiveForNow | V20: =RANK(T20, T:T) -> 240 | X20: 3888 | Y20: 128 | Z20: #LiveForNow | AA20: =X20+Y20 -> 4016
A21: P020 | B21: Instagram | C21: 2024-09-09 | D21: Carousel | E21: Check out our latest carousel on instagram! | F21: 4054 | G21: 488 | H21: 373 | I21: 77026 | J21: 76881 | K21: 25 | L21: #PepsiCoRefresh | M21: SummerSplash | N21: #PepsiCoRefresh | Q21: =(F21+G21+H21)/I21 -> 0.063809623 | R21: =F21+G21+H21 -> 4915 | T21: 159 | U21: #ThirstyForMore | V21: =RANK(T21, T:T) -> 166 | X21: 3452 | Y21: 360 | Z21: #LiveForNow | AA21: =X21+Y21 -> 3812
A22: P021 | B22: Instagram | C22: 2025-01-04 | D22: Reel | E22: Check out our latest reel on instagram! | F22: 4838 | G22: 640 | H22: 128 | I22: 72570 | J22: 72396 | K22: 83 | L22: #LiveForNow | M22: DailyWellness | N22: #LiveForNow | Q22: =(F22+G22+H22)/I22 -> 0.077249552 | R22: =F22+G22+H22 -> 5606 | T22: 19 | U22: #LiveForNow | V22: =RANK(T22, T:T) -> 319 | X22: 4441 | Y22: 70 | Z22: #ThirstyForMore | AA22: =X22+Y22 -> 4511
A23: P022 | B23: Facebook | C23: 2025-02-27 | D23: Text | E23: Check out our latest text on facebook! | F23: 1570 | G23: 187 | H23: 260 | I23: 25120 | J23: 24613 | K23: 133 | L23: #PepsiCoRefresh | M23: DailyWellness | N23: #PepsiCoRefresh | Q23: =(F23+G23+H23)/I23 -> 0.080294586 | R23: =F23+G23+H23 -> 2017 | T23: 103 | U23: #PepsiCoRefresh | V23: =RANK(T23, T:T) -> 226 | X23: 3000 | Y23: 325 | Z23: #LiveForNow | AA23: =X23+Y23 -> 3325
A24: P023 | B24: Facebook | C24: 2024-11-06 | D24: Video | E24: Check out our latest video on facebook! | F24: 1606 | G24: 547 | H24: 316 | I24: 32120 | J24: 31736 | K24: 225 | L24: #PepsiCoRefresh,#AnytimeIsPepsiTime | M24: FestiveRadiance | N24: #PepsiCoRefresh | O24: #AnytimeIsPepsiTime | Q24: =(F24+G24+H24)/I24 -> 0.076867995 | R24: =F24+G24+H24 -> 2469 | T24: 25 | U24: #PepsiCoRefresh | V24: =RANK(T24, T:T) -> 304 | X24: 1071 | Y24: 22 | Z24: #PepsiCoRefresh | AA24: =X24+Y24 -> 1093
A25: P024 | B25: Facebook | C25: 2025-01-23 | D25: Video | E25: Check out our latest video on facebook! | F25: 3961 | G25: 761 | H25: 131 | I25: 67337 | J25: 66615 | K25: 161 | L25: #LiveForNow | M25: NewYearRefresh | N25: #LiveForNow | Q25: =(F25+G25+H25)/I25 -> 0.072070333 | R25: =F25+G25+H25 -> 4853 | T25: 83 | U25: #LiveForNow | V25: =RANK(T25, T:T) -> 248 | X25: 4054 | Y25: 373 | Z25: #PepsiCoRefresh | AA25: =X25+Y25 -> 4427
A26: P025 | B26: Twitter | C26: 2025-04-10 | D26: Carousel | E26: Check out our latest carousel on twitter! | F26: 3128 | G26: 211 | H26: 197 | I26: 59432 | J26: 59182 | K26: 238 | L26: #ThirstyForMore | N26: #ThirstyForMore | Q26: =(F26+G26+H26)/I26 -> 0.059496568 | R26: =F26+G26+H26 -> 3536 | T26: 133 | U26: #PepsiCoRefresh | V26: =RANK(T26, T:T) -> 191 | X26: 4838 | Y26: 128 | Z26: #LiveForNow | AA26: =X26+Y26 -> 4966
A27: P026 | B27: YouTube | C27: 2025-04-05 | D27: Reel | E27: Check out our latest reel on youtube! | F27: 3009 | G27: 413 | H27: 358 | I27: 42126 | J27: 41309 | K27: 211 | L27: #LiveForNow | M27: FestiveRadiance | N27: #LiveForNow | Q27: =(F27+G27+H27)/I27 -> 0.089730808 | R27: =F27+G27+H27 -> 3780 | T27: 225 | U27: #PepsiCoRefresh | V27: =RANK(T27, T:T) -> 85 | X27: 1570 | Y27: 260 | Z27: #PepsiCoRefresh | AA27: =X27+Y27 -> 1830
A28: P027 | B28: YouTube | C28: 2024-09-17 | D28: Text | E28: Check out our latest text on youtube! | F28: 2076 | G28: 195 | H28: 104 | I28: 33216 | J28: 32244 | K28: 51 | L28: #LiveForNow | M28: DailyWellness | N28: #LiveForNow | Q28: =(F28+G28+H28)/I28 -> 0.071501686 | R28: =F28+G28+H28 -> 2375 | T28: 225 | U28: #AnytimeIsPepsiTime | V28: =RANK(T28, T:T) -> 85 | X28: 1606 | Y28: 316 | Z28: #PepsiCoRefresh | AA28: =X28+Y28 -> 1922
A29: P028 | B29: Instagram | C29: 2025-03-04 | D29: Video | E29: Check out our latest video on instagram! | F29: 432 | G29: 624 | H29: 123 | I29: 6912 | J29: 6259 | K29: 79 | L29: #LiveForNow | M29: DailyWellness | N29: #LiveForNow | Q29: =(F29+G29+H29)/I29 -> 0.17057292 | R29: =F29+G29+H29 -> 1179 | T29: 161 | U29: #LiveForNow | V29: =RANK(T29, T:T) -> 164 | X29: 1606 | Y29: 316 | Z29: #AnytimeIsPepsiTime | AA29: =X29+Y29 -> 1922
A30: P029 | B30: Instagram | C30: 2025-01-31 | D30: Carousel | E30: Check out our latest carousel on instagram! | F30: 2566 | G30: 118 | H30: 37 | I30: 12830 | J30: 12264 | K30: 221 | L30: #LiveForNow | M30: NewYearRefresh | N30: #LiveForNow | Q30: =(F30+G30+H30)/I30 -> 0.21208106 | R30: =F30+G30+H30 -> 2721 | T30: 238 | U30: #ThirstyForMore | V30: =RANK(T30, T:T) -> 63 | X30: 3961 | Y30: 131 | Z30: #LiveForNow | AA30: =X30+Y30 -> 4092
A31: P030 | B31: Instagram | C31: 2025-02-25 | D31: Video | E31: Check out our latest video on instagram! | F31: 3095 | G31: 39 | H31: 78 | I31: 55710 | J31: 54808 | K31: 93 | L31: #ThirstyForMore | N31: #ThirstyForMore | Q31: =(F31+G31+H31)/I31 -> 0.057655717 | R31: =F31+G31+H31 -> 3212 | T31: 211 | U31: #LiveForNow | V31: =RANK(T31, T:T) -> 104 | X31: 3128 | Y31: 197 | Z31: #ThirstyForMore | AA31: =X31+Y31 -> 3325
A32: P031 | B32: Instagram | C32: 2024-12-16 | D32: Text | E32: Check out our latest text on instagram! | F32: 438 | G32: 153 | H32: 275 | I32: 3066 | J32: 2701 | K32: 282 | L32: #PepsiCoRefresh | M32: FestiveRadiance | N32: #PepsiCoRefresh | Q32: =(F32+G32+H32)/I32 -> 0.28245271 | R32: =F32+G32+H32 -> 866 | T32: 51 | U32: #LiveForNow | V32: =RANK(T32, T:T) -> 275 | X32: 3009 | Y32: 358 | Z32: #LiveForNow | AA32: =X32+Y32 -> 3367
A33: P032 | B33: Twitter | C33: 2024-07-31 | D33: Carousel | E33: Check out our latest carousel on twitter! | F33: 2278 | G33: 10 | H33: 321 | I33: 13668 | J33: 12676 | K33: 275 | L33: #ThirstyForMore | M33: SummerSplash | N33: #ThirstyForMore | Q33: =(F33+G33+H33)/I33 -> 0.19088382 | R33: =F33+G33+H33 -> 2609 | T33: 79 | U33: #LiveForNow | V33: =RANK(T33, T:T) -> 251 | X33: 2076 | Y33: 104 | Z33: #LiveForNow | AA33: =X33+Y33 -> 2180
A34: P033 | B34: Facebook | C34: 2024-08-21 | D34: Image | E34: Check out our latest image on facebook! | F34: 1407 | G34: 400 | H34: 351 | I34: 16884 | J34: 15954 | K34: 113 | L34: #PepsiCoRefresh | M34: SummerSplash | N34: #PepsiCoRefresh | Q34: =(F34+G34+H34)/I34 -> 0.12781331 | R34: =F34+G34+H34 -> 2158 | T34: 221 | U34: #LiveForNow | V34: =RANK(T34, T:T) -> 93 | X34: 432 | Y34: 123 | Z34: #LiveForNow | AA34: =X34+Y34 -> 555
A35: P034 | B35: Facebook | C35: 2025-03-26 | D35: Text | E35: Check out our latest text on facebook! | F35: 1652 | G35: 89 | H35: 357 | I35: 29736 | J35: 28771 | K35: 215 | L35: #PepsiCoRefresh | M35: NewYearRefresh | N35: #PepsiCoRefresh | Q35: =(F35+G35+H35)/I35 -> 0.07055421 | R35: =F35+G35+H35 -> 2098 | T35: 93 | U35: #ThirstyForMore | V35: =RANK(T35, T:T) -> 232 | X35: 2566 | Y35: 37 | Z35: #LiveForNow | AA35: =X35+Y35 -> 2603
A36: P035 | B36: Instagram | C36: 2024-11-30 | D36: Video | E36: Check out our latest video on instagram! | F36: 3775 | G36: 16 | H36: 239 | I36: 33975 | J36: 33310 | K36: 271 | L36: #LiveForNow | M36: FestiveRadiance | N36: #LiveForNow | Q36: =(F36+G36+H36)/I36 -> 0.11861663 | R36: =F36+G36+H36 -> 4030 | T36: 282 | U36: #PepsiCoRefresh | V36: =RANK(T36, T:T) -> 15 | X36: 3095 | Y36: 78 | Z36: #ThirstyForMore | AA36: =X36+Y36 -> 3173
A37: P036 | B37: Instagram | C37: 2025-04-19 | D37: Story | E37: Check out our latest story on instagram! | F37: 4518 | G37: 285 | H37: 383 | I37: 67770 | J37: 67621 | K37: 31 | L37: #ThirstyForMore | M37: FestiveRadiance | N37: #ThirstyForMore | Q37: =(F37+G37+H37)/I37 -> 0.076523535 | R37: =F37+G37+H37 -> 5186 | T37: 275 | U37: #ThirstyForMore | V37: =RANK(T37, T:T) -> 25 | X37: 438 | Y37: 275 | Z37: #PepsiCoRefresh | AA37: =X37+Y37 -> 713
A38: P037 | B38: Facebook | C38: 2025-01-06 | D38: Carousel | E38: Check out our latest carousel on facebook! | F38: 3024 | G38: 925 | H38: 350 | I38: 24192 | J38: 23518 | K38: 36 | L38: #ThirstyForMore | M38: FestiveRadiance | N38: #ThirstyForMore | Q38: =(F38+G38+H38)/I38 -> 0.17770337 | R38: =F38+G38+H38 -> 4299 | T38: 113 | U38: #PepsiCoRefresh | V38: =RANK(T38, T:T) -> 219 | X38: 2278 | Y38: 321 | Z38: #ThirstyForMore | AA38: =X38+Y38 -> 2599
A39: P038 | B39: YouTube | C39: 2025-02-17 | D39: Reel | E39: Check out our latest reel on youtube! | F39: 3138 | G39: 123 | H39: 291 | I39: 28242 | J39: 27550 | K39: 87 | L39: #PepsiCoRefresh | M39: DailyWellness | N39: #PepsiCoRefresh | Q39: =(F39+G39+H39)/I39 -> 0.12577013 | R39: =F39+G39+H39 -> 3552 | T39: 215 | U39: #PepsiCoRefresh | V39: =RANK(T39, T:T) -> 99 | X39: 1407 | Y39: 351 | Z39: #PepsiCoRefresh | AA39: =X39+Y39 -> 1758
A40: P039 | B40: Facebook | C40: 2024-11-25 | D40: Image | E40: Check out our latest image on facebook! | F40: 3564 | G40: 629 | H40: 177 | I40: 60588 | J40: 59627 | K40: 92 | L40: #PepsiCoRefresh | N40: #PepsiCoRefresh | Q40: =(F40+G40+H40)/I40 -> 0.072126494 | R40: =F40+G40+H40 -> 4370 | T40: 271 | U40: #LiveForNow | V40: =RANK(T40, T:T) -> 29 | X40: 1652 | Y40: 357 | Z40: #PepsiCoRefresh | AA40: =X40+Y40 -> 2009
...

Sheet Engagement Summary
A1: Week_Start_Date | B1: Platform | C1: New_Followers | D1: Unfollows | E1: Total_Followers | F1: Engagement_Rate | G1: Ad_Spend
A2: 45446 | B2: Instagram | C2: 1135 | D2: 88 | E2: 344084 | F2: 8.06 | G2: 5904
A3: 45446 | B3: Facebook | C3: 1312 | D3: 310 | E3: 42654 | F3: 4.98 | G3: 9566
A4: 45446 | B4: Twitter | C4: 584 | D4: 169 | E4: 146834 | F4: 8.31 | G4: 26752
A5: 45446 | B5: YouTube | C5: 1535 | D5: 445 | E5: 395536 | F5: 4.11 | G5: 30671
A6: 45453 | B6: Instagram | C6: 656 | D6: 139 | E6: 49157 | F6: 9.05 | G6: 9920
A7: 45453 | B7: Facebook | C7: 1697 | D7: 414 | E7: 316555 | F7: 2.37 | G7: 7924
A8: 45453 | B8: Twitter | C8: 436 | D8: 250 | E8: 254347 | F8: 4.01 | G8: 8912
A9: 45453 | B9: YouTube | C9: 1197 | D9: 203 | E9: 413878 | F9: 3.16 | G9: 21205
A10: 45460 | B10: Instagram | C10: 1048 | D10: 155 | E10: 456946 | F10: 2.46 | G10: 11329
A11: 45460 | B11: Facebook | C11: 1753 | D11: 371 | E11: 169496 | F11: 8.11 | G11: 46670
A12: 45460 | B12: Twitter | C12: 1335 | D12: 40 | E12: 122732 | F12: 8.19 | G12: 22482
A13: 45460 | B13: YouTube | C13: 403 | D13: 66 | E13: 382851 | F13: 3.49 | G13: 24313
... A201: 45789 | B201: YouTube | C201: 119 | D201: 456 | E201: 82558 | F201: 6.81 | G201: 12174

Sheet Campaign Metadata
A1: Campaign_Name | B1: Start_Date | C1: End_Date | D1: Objective | E1: Total_Budget | F1: Target_Platforms | G1: Primary_Hashtags
A2: SummerSplash | B2: 45458 | C2: 45488 | D2: Brand Awareness | E2: 150000 | F2: Instagram,Facebook | G2: #ThirstyForMore,#PepsiCoRefresh
A3: FestiveRadiance | B3: 45566 | C3: 45596 | D3: Engagement | E3: 200000 | F3: Instagram,YouTube | G3: #AnytimeIsPepsiTime,
A4: NewYearRefresh | B4: 45651 | C4: 45667 | D4: Product Launch | E4: 250000 | F4: Facebook,Twitter | G4: #SmoothLikeNitroPepsi
A5: DailyWellness | B5: 45717 | C5: 45747 | D5: Traffic | E5: 180000 | F5: Instagram,Twitter | G5: #BetterWithPepsi,#LiveForNow
